Workbook

Sheet Control Sheet
B2: InterGlobe Aviation
B3: Control Sheet
J5: Current Case | K5: 1
J8: Actual | L8: Explicit Forecast Period
B9: In INR Crores unless stated otherwise | F9: =G9-1 -> 2021 | G9: =H9-1 -> 2022 | H9: =I9-1 -> 2023 | I9: =J9-1 -> 2024 | J9: 2025 | K9: =J9+1 -> 2026 | L9: =K9+1 -> 2027 | M9: =L9+1 -> 2028 | N9: =M9+1 -> 2029 | O9: =N9+1 -> 2030 | P9: =O9+1 -> 2031
B10: Assumptions
A11: # | B11: Revenue
B13: Revenue YoY % Growth
B14: Management Case | L14: 0.198 | M14: 0.198 | N14: 0.198 | O14: 0.198 | P14: 0.198
B15: Best Case | L15: 0.198 | M15: 0.198 | N15: 0.198 | O15: 0.198 | P15: 0.198
B16: Down Case | L16: 0.198 | M16: 0.198 | N16: 0.198 | O16: 0.198 | P16: 0.198
B17: ="Current Case - "& CHOOSE($K$5,$B$14,$B$15,$B$16) -> Current Case - Management Case | L17: =CHOOSE($K$5,L14,L15,L16) -> 0.198 | M17: =CHOOSE($K$5,M14,M15,M16) -> 0.198 | N17: =CHOOSE($K$5,N14,N15,N16) -> 0.198 | O17: =CHOOSE($K$5,O14,O15,O16) -> 0.198 | P17: =CHOOSE($K$5,P14,P15,P16) -> 0.198
B19: Passenger service YoY Growth %
B20: Management Case | L20: 0.2 | M20: 0.2 | N20: 0.2 | O20: 0.2 | P20: 0.2
B21: Best Case | L21: 0.2 | M21: 0.2 | N21: 0.2 | O21: 0.2 | P21: 0.2
B22: Down Case | L22: 0.2 | M22: 0.2 | N22: 0.2 | O22: 0.2 | P22: 0.2
B23: ="Current Case - "& CHOOSE($K$5,$B$14,$B$15,$B$16) -> Current Case - Management Case | L23: =CHOOSE($K$5,L20,L21,L22) -> 0.2 | M23: =CHOOSE($K$5,M20,M21,M22) -> 0.2 | N23: =CHOOSE($K$5,N20,N21,N22) -> 0.2 | O23: =CHOOSE($K$5,O20,O21,O22) -> 0.2 | P23: =CHOOSE($K$5,P20,P21,P22) -> 0.2
B25: Cargo Service YoY Growth %
B26: Management Case | L26: 0.15 | M26: 0.15 | N26: 0.15 | O26: 0.15 | P26: 0.15
B27: Best Case | L27: 0.15 | M27: 0.15 | N27: 0.15 | O27: 0.15 | P27: 0.15
B28: Down Case | L28: 0.15 | M28: 0.15 | N28: 0.15 | O28: 0.15 | P28: 0.15
B29: ="Current Case - "& CHOOSE($K$5,$B$14,$B$15,$B$16) -> Current Case - Management Case | L29: =CHOOSE($K$5,L26,L27,L28) -> 0.15 | M29: =CHOOSE($K$5,M26,M27,M28) -> 0.15 | N29: =CHOOSE($K$5,N26,N27,N28) -> 0.15 | O29: =CHOOSE($K$5,O26,O27,O28) -> 0.15 | P29: =CHOOSE($K$5,P26,P27,P28) -> 0.15
B31: In flight sales YoY Growth %
B32: Management Case | L32: 0.18 | M32: 0.18 | N32: 0.18 | O32: 0.18 | P32: 0.18
B33: Best Case | L33: 0.18 | M33: 0.18 | N33: 0.18 | O33: 0.18 | P33: 0.18
B34: Down Case | L34: 0.18 | M34: 0.18 | N34: 0.18 | O34: 0.18 | P34: 0.18
B35: ="Current Case - "& CHOOSE($K$5,$B$14,$B$15,$B$16) -> Current Case - Management Case | L35: =CHOOSE($K$5,L32,L33,L34) -> 0.18 | M35: =CHOOSE($K$5,M32,M33,M34) -> 0.18 | N35: =CHOOSE($K$5,N32,N33,N34) -> 0.18 | O35: =CHOOSE($K$5,O32,O33,O34) -> 0.18 | P35: =CHOOSE($K$5,P32,P33,P34) -> 0.18
B37: Others YoY Growth %
B38: Management Case | L38: 0.1 | M38: 0.1 | N38: 0.1 | O38: 0.1 | P38: 0.1
B39: Best Case | L39: 0.1 | M39: 0.1 | N39: 0.1 | O39: 0.1 | P39: 0.1
B40: Down Case | L40: 0.1 | M40: 0.1 | N40: 0.1 | O40: 0.1 | P40: 0.1
B41: ="Current Case - "& CHOOSE($K$5,$B$14,$B$15,$B$16) -> Current Case - Management Case | L41: =CHOOSE($K$5,L38,L39,L40) -> 0.1 | M41: =CHOOSE($K$5,M38,M39,M40) -> 0.1 | N41: =CHOOSE($K$5,N38,N39,N40) -> 0.1 | O41: =CHOOSE($K$5,O38,O39,O40) -> 0.1 | P41: =CHOOSE($K$5,P38,P39,P40) -> 0.1
A43: # | B43: Cost of Goods Sold
B45: Gross Margin % Sales
B46: Management Case | F46: ='Income Statement'!J$33 -> 0.35464981 | G46: ='Income Statement'!K$33 -> 0.25028349 | H46: ='Income Statement'!L$33 -> 0.2853641 | I46: ='Income Statement'!M$33 -> 0.41084954 | J46: ='Income Statement'!N$33 -> 0.40373056 | K46: ='Income Statement'!O$33 -> 0.33611654 | L46: =K46-(($K$46-$O$46)/($O$9-$K$9)) -> 0.37708741 | M46: =L46-(($K$46-$O$46)/($O$9-$K$9)) -> 0.41805827 | N46: =M46-(($K$46-$O$46)/($O$9-$K$9)) -> 0.45902914 | O46: 0.5 | P46: 0.5
B47: Best Case | F47: ='Income Statement'!J$33 -> 0.35464981 | G47: ='Income Statement'!K$33 -> 0.25028349 | H47: ='Income Statement'!L$33 -> 0.2853641 | I47: ='Income Statement'!M$33 -> 0.41084954 | J47: ='Income Statement'!N$33 -> 0.40373056 | K47: ='Income Statement'!O$33 -> 0.33611654 | L47: =K47-(($K$47-$O$47)/($O$9-$K$9)) -> 0.38958741 | M47: =L47-(($K$47-$O$47)/($O$9-$K$9)) -> 0.44305827 | N47: =M47-(($K$47-$O$47)/($O$9-$K$9)) -> 0.49652914 | O47: 0.55 | P47: 0.55
B48: Down Case | F48: ='Income Statement'!J$33 -> 0.35464981 | G48: ='Income Statement'!K$33 -> 0.25028349 | H48: ='Income Statement'!L$33 -> 0.2853641 | I48: ='Income Statement'!M$33 -> 0.41084954 | J48: ='Income Statement'!N$33 -> 0.40373056 | K48: ='Income Statement'!O$33 -> 0.33611654 | L48: =K48-(($K$48-$O$48)/($O$9-$K$9)) -> 0.33958741 | M48: =L48-(($K$48-$O$48)/($O$9-$K$9)) -> 0.34305827 | N48: =M48-(($K$48-$O$48)/($O$9-$K$9)) -> 0.34652914 | O48: 0.35 | P48: 0.35
B49: ="Current Case - "& CHOOSE($K$5,$B$14,$B$15,$B$16) -> Current Case - Management Case | F49: =CHOOSE($K$5,F46,F47,F48) -> 0.35464981 | G49: =CHOOSE($K$5,G46,G47,G48) -> 0.25028349 | H49: =CHOOSE($K$5,H46,H47,H48) -> 0.2853641 | I49: =CHOOSE($K$5,I46,I47,I48) -> 0.41084954 | J49: =CHOOSE($K$5,J46,J47,J48) -> 0.40373056 | K49: =CHOOSE($K$5,K46,K47,K48) -> 0.33611654 | L49: =CHOOSE($K$5,L46,L47,L48) -> 0.37708741 | M49: =CHOOSE($K$5,M46,M47,M48) -> 0.41805827 | ... P49: =CHOOSE($K$5,P46,P47,P48) -> 0.5
B51: COGS % Sales | F51: =1-F49 -> 0.64535019 | G51: =1-G49 -> 0.74971651 | H51: =1-H49 -> 0.7146359 | I51: =1-I49 -> 0.58915046 | J51: =1-J49 -> 0.59626944 | K51: =1-K49 -> 0.66388346 | L51: 0.66 | M51: 0.66 | N51: 0.66 | O51: 0.66 | P51: 0.66
B53: Selling, General and Administrative (SG&A) Expenses
...

Sheet Schedule Sheet
D1: ḥ
B2: ='Control Sheet'!B2 -> InterGlobe Aviation
B3: Schedule Sheet
I5: Current Case | J5: 0
D8: Actual | J8: Explicit Forecast Period
B9: In INR Crores unless stated otherwise | D9: 2021 | E9: =D9+1 -> 2022 | F9: =E9+1 -> 2023 | G9: =F9+1 -> 2024 | H9: 2025 | I9: =H9+1 -> 2026 | J9: =I9+1 -> 2027 | K9: =J9+1 -> 2028 | L9: =K9+1 -> 2029 | M9: =L9+1 -> 2030 | N9: =M9+1 -> 2031
B11: Sales Schedule
B13: Revenue | D13: ='Income Statement'!J12 -> 146406.31 | E13: ='Income Statement'!K12 -> 259309.27 | F13: ='Income Statement'!L12 -> 544464.53 | G13: ='Income Statement'!M12 -> 689043 | H13: ='Income Statement'!N12 -> 808029 | I13: ='Income Statement'!O12 -> 849619 | J13: =SUM(J14,J16,J18,J20) -> 1015783.4 | K13: =SUM(K14,K16,K18,K20) -> 1214721.6 | L13: =SUM(L14,L16,L18,L20) -> 1452929.1 | M13: =SUM(M14,M16,M18,M20) -> 1738192.8 | N13: =SUM(N14,N16,N18,N20) -> 2079847.9
B14: Passenger service | D14: 129619.69 | E14: 239102.72 | F14: 512577.6 | G14: 646089.29 | H14: 742111 | I14: 789026 | J14: =I14*J15+I14 -> 946831.2 | K14: =J14*K15+J14 -> 1136197.4 | L14: =K14*L15+K14 -> 1363436.9 | M14: =L14*M15+L14 -> 1636124.3 | N14: =M14*N15+M14 -> 1963349.2
J15: ='Control Sheet'!L23 -> 0.2 | K15: ='Control Sheet'!M23 -> 0.2 | L15: ='Control Sheet'!N23 -> 0.2 | M15: ='Control Sheet'!O23 -> 0.2 | N15: ='Control Sheet'!P23 -> 0.2
B16: Cargo Service | D16: 11451.02 | E16: 14974.65 | F16: 15837.01 | G16: 17943.97 | H16: 22651 | I16: 24837 | J16: =I16*J17+I16 -> 28562.55 | K16: =J16*K17+J16 -> 32846.932 | L16: =K16*L17+K16 -> 37773.972 | M16: =L16*M17+L16 -> 43440.068 | N16: =M16*N17+M16 -> 49956.078
J17: ='Control Sheet'!L29 -> 0.15 | K17: ='Control Sheet'!M29 -> 0.15 | L17: ='Control Sheet'!N29 -> 0.15 | M17: ='Control Sheet'!O29 -> 0.15 | N17: ='Control Sheet'!P29 -> 0.15
B18: In flight sales | D18: 1028.25 | E18: 2462.31 | F18: 7662.06 | G18: 9835.39 | H18: 11424 | I18: 13226 | J18: =I18*J19+I18 -> 15606.68 | K18: =J18*K19+J18 -> 18415.882 | L18: =K18*L19+K18 -> 21730.741 | M18: =L18*M19+L18 -> 25642.275 | N18: =M18*N19+M18 -> 30257.884
J19: ='Control Sheet'!L35 -> 0.18 | K19: ='Control Sheet'!M35 -> 0.18 | L19: ='Control Sheet'!N35 -> 0.18 | M19: ='Control Sheet'!O35 -> 0.18 | N19: ='Control Sheet'!P35 -> 0.18
B20: Others | D20: 4307.35 | E20: 2769.59 | F20: 8387.86 | G20: 15174.35 | H20: 31843 | I20: 22530 | J20: =I20*J21+I20 -> 24783 | K20: =J20*K21+J20 -> 27261.3 | L20: =K20*L21+K20 -> 29987.43 | M20: =L20*M21+L20 -> 32986.173 | N20: =M20*N21+M20 -> 36284.79
J21: ='Control Sheet'!L41 -> 0.1 | K21: ='Control Sheet'!M41 -> 0.1 | L21: ='Control Sheet'!N41 -> 0.1 | M21: ='Control Sheet'!O41 -> 0.1 | N21: ='Control Sheet'!P41 -> 0.1
B23: Cost of Goods Sold Schedule
B25: COGS % Sales | J25: ='Control Sheet'!L51 -> 0.66 | K25: ='Control Sheet'!M51 -> 0.66 | L25: ='Control Sheet'!N51 -> 0.66 | M25: ='Control Sheet'!O51 -> 0.66 | N25: ='Control Sheet'!P51 -> 0.66
B26: COGS | D26: ='Income Statement'!J25 -> 94483.34 | E26: ='Income Statement'!K25 -> 194408.44 | F26: ='Income Statement'!L25 -> 389093.9 | G26: ='Income Statement'!M25 -> 405950 | H26: ='Income Statement'!N25 -> 481803 | I26: ='Income Statement'!O25 -> 564048 | J26: =J13*J25 -> 670417.06 | K26: =K13*K25 -> 801716.23 | L26: =L13*L25 -> 958933.19 | M26: =M13*M25 -> 1147207.3 | N26: =N13*N25 -> 1372699.6
D27: =D26/D13 -> 0.64535019 | E27: =E26/E13 -> 0.74971651 | F27: =F26/F13 -> 0.7146359 | G27: =G26/G13 -> 0.58915046 | H27: =H26/H13 -> 0.59626944 | I27: =I26/I13 -> 0.66388346
B28: SG&A (Excluding Depreciation and Interest Expenses) Schedule
D29: =AVERAGE(D27:I27) -> 0.65983433
B30: Employee Benefit Expenses | D30: ='Income Statement'!J36 -> 32954.92 | E30: ='Income Statement'!K36 -> 34864.43 | F30: ='Income Statement'!L36 -> 47947.52 | G30: ='Income Statement'!M36 -> 64618 | H30: ='Income Statement'!N36 -> 74725 | I30: ='Income Statement'!O36 -> 82722 | J30: =J13*J31 -> 101578.34 | K30: =K13*K31 -> 121472.16 | L30: =L13*L31 -> 188880.78 | M30: =M13*M31 -> 260728.92 | N30: =N13*N31 -> 311977.19
B31: Employee Benefit Expenses % Revenue | D31: =D30/D13 -> 0.22509221 | E31: =E30/E13 -> 0.13445115 | F31: =F30/F13 -> 0.088063625 | G31: =G30/G13 -> 0.093779343 | H31: =H30/H13 -> 0.092478117 | I31: ='Control Sheet'!K59 -> 0.097363642 | J31: 0.1 | K31: 0.1 | L31: 0.13 | M31: 0.15 | N31: 0.15
B33: Other Expenses | D33: ='Income Statement'!J37 -> 19104.1 | E33: ='Income Statement'!K37 -> 24563.07 | F33: ='Income Statement'!L37 -> 42469.61 | G33: ='Income Statement'!M37 -> 55300 | H33: ='Income Statement'!N37 -> 70918 | I33: ='Income Statement'!O37 -> 83015 | J33: =J13*J34 -> 91420.509 | K33: =K13*K34 -> 109324.94 | L33: =L13*L34 -> 130763.62 | M33: =M13*M34 -> 156437.35 | N33: =N13*N34 -> 187186.31
B34: Other Expenses % Revenue | D34: =D33/D13 -> 0.13048686 | E34: =E33/E13 -> 0.094724998 | F34: =F33/F13 -> 0.078002528 | G34: =G33/G13 -> 0.080256239 | H34: =H33/H13 -> 0.087766652 | I34: =I33/I13 -> 0.097708502 | J34: ='Control Sheet'!L65 -> 0.09 | K34: ='Control Sheet'!M65 -> 0.09 | L34: ='Control Sheet'!N65 -> 0.09 | M34: ='Control Sheet'!O65 -> 0.09 | N34: ='Control Sheet'!P65 -> 0.09
B36: Total SG&A | D36: =D33+D30 -> 52059.02 | E36: =E33+E30 -> 59427.5 | F36: =F33+F30 -> 90417.13 | G36: =G33+G30 -> 119918 | H36: =H33+H30 -> 145643 | I36: =I33+I30 -> 165737 | J36: =J33+J30 -> 192998.85 | K36: =K33+K30 -> 230797.1 | ... N36: =N33+N30 -> 499163.5
B37: Total SG&A % Revenue | D37: =D36/D13 -> 0.35557907 | E37: =E36/E13 -> 0.22917615 | F37: =F36/F13 -> 0.16606615 | G37: =G36/G13 -> 0.17403558 | H37: =H36/H13 -> 0.18024477 | I37: =I36/I13 -> 0.19507214 | J37: =J36/J13 -> 0.19 | K37: =K36/K13 -> 0.19 | ... N37: =N36/N13 -> 0.24
B39: Non-Current Asset Schedule
B41: ='Control Sheet'!B71 -> Plant, machinery and equipment Growth %
B43: Opening PM&E | J43: ='Balance Sheet'!O9 -> 110871 | K43: =J46 -> 117767.33 | L43: =K46 -> 124424.94 | M43: =L46 -> 130673.22 | N43: =M46 -> 136305.67
B44: Add: Capex during the year | J44: =I46*J47 -> 27717.75 | K44: =J46*K47 -> 29441.831 | L44: =K46*L47 -> 31106.236 | M44: =L46*M47 -> 32668.304 | N44: =M46*N47 -> 34076.418
B45: Less: Depreciation | I45: =('Income Statement'!O48)/SUM('Balance Sheet'!O9,'Balance Sheet'!O10,'Balance Sheet'!O12)*'Balance Sheet'!O9 -> 18973.575 | J45: =I45+J44/$C$90 -> 20821.425 | K45: =J45+K44/$C$90 -> 22784.213 | L45: =K45+L44/$C$90 -> 24857.962 | M45: =L45+M44/$C$90 -> 27035.849 | N45: =M45+N44/$C$90 -> 29307.61
B46: Closing PM&E | I46: ='Balance Sheet'!O9 -> 110871 | J46: =J43+J44-J45 -> 117767.33 | K46: =K43+K44-K45 -> 124424.94 | L46: =L43+L44-L45 -> 130673.22 | M46: =M43+M44-M45 -> 136305.67 | N46: =N43+N44-N45 -> 141074.48
J47: ='Control Sheet'!L75 -> 0.25 | K47: ='Control Sheet'!M75 -> 0.25 | L47: ='Control Sheet'!N75 -> 0.25 | M47: ='Control Sheet'!O75 -> 0.25 | N47: ='Control Sheet'!P75 -> 0.25
B49: Right of use assets | J49: ='Balance Sheet'!O10 -> 520540 | K49: =J52 -> 552918.29 | L49: =K52 -> 584175.85 | M49: =L52 -> 613511.53 | N49: =M52 -> 639955.94
B50: Addition during the year | J50: =I52*J53 -> 130135 | K50: =J52*K53 -> 138229.57 | L50: =K52*L53 -> 146043.96 | M50: =L52*M53 -> 153377.88 | N50: =M52*N53 -> 159988.98
B51: Less: Depreciation | I51: ='Income Statement'!O48/SUM('Balance Sheet'!O9,'Balance Sheet'!O10,'Balance Sheet'!O12)*'Balance Sheet'!O10 -> 89081.044 | J51: =I51+J50/$C$90 -> 97756.711 | K51: =J51+K50/$C$90 -> 106972.02 | L51: =K51+L50/$C$90 -> 116708.28 | M51: =L51+M50/$C$90 -> 126933.47 | N51: =M51+N50/$C$90 -> 137599.4
B52: Closing Right of use assets | I52: ='Balance Sheet'!O10 -> 520540 | J52: =J49+J50-J51 -> 552918.29 | K52: =K49+K50-K51 -> 584175.85 | L52: =L49+L50-L51 -> 613511.53 | M52: =M49+M50-M51 -> 639955.94 | N52: =N49+N50-N51 -> 662345.52
B53: YoY Growth % | J53: ='Control Sheet'!L81 -> 0.25 | K53: ='Control Sheet'!M81 -> 0.25 | L53: ='Control Sheet'!N81 -> 0.25 | M53: ='Control Sheet'!O81 -> 0.25 | N53: ='Control Sheet'!P81 -> 0.25
...

Sheet 3 Statement Model
B2: ='Control Sheet'!B2 -> InterGlobe Aviation
B3: 3 Statement Model
J5: Current Case | K5: 0
P7: CAGR
D8: Actual | J8: Explicit Forecast Period | P8: 5 Years | Q8: 3 Years
B9: In INR Crores unless stated otherwise | D9: 2021 | E9: =D9+1 -> 2022 | F9: =E9+1 -> 2023 | G9: =F9+1 -> 2024 | H9: =G9+1 -> 2025 | I9: =H9+1 -> 2026 | J9: =I9+1 -> 2027 | K9: =J9+1 -> 2028 | L9: =K9+1 -> 2029 | ... N9: =M9+1 -> 2031
B11: Income Statement
B13: Revenue | D13: ='Schedule Sheet'!D13 -> 146406.31 | E13: ='Schedule Sheet'!E13 -> 259309.27 | F13: ='Schedule Sheet'!F13 -> 544464.53 | G13: ='Schedule Sheet'!G13 -> 689043 | H13: ='Schedule Sheet'!H13 -> 808029 | I13: ='Schedule Sheet'!I13 -> 849619 | J13: ='Schedule Sheet'!J13 -> 1015783.4 | K13: ='Schedule Sheet'!K13 -> 1214721.6 | ... N13: ='Schedule Sheet'!N13 -> 2079847.9 | P13: =IF(OR(I13<=0,N13<=0),"NM",_xlfn.RRI($N$9-$I$9,I13,N13)) -> 0.19608343 | Q13: =IF(OR(K13<=0,N13<=0),"NM",_xlfn.RRI($N$9-$K$9,K13,N13)) -> 0.19633171
B14: Less: Cost of Goods Sold | D14: ='Schedule Sheet'!D26*-1 -> -94483.34 | E14: ='Schedule Sheet'!E26*-1 -> -194408.44 | F14: ='Schedule Sheet'!F26*-1 -> -389093.9 | G14: ='Schedule Sheet'!G26*-1 -> -405950 | H14: ='Schedule Sheet'!H26*-1 -> -481803 | I14: ='Schedule Sheet'!I26*-1 -> -564048 | J14: ='Schedule Sheet'!J26*-1 -> -670417.06 | K14: ='Schedule Sheet'!K26*-1 -> -801716.23 | ... N14: ='Schedule Sheet'!N26*-1 -> -1372699.6 | P14: =_xlfn.RRI($N$9-$I$9,I14,N14) -> 0.19468082 | Q14: =_xlfn.RRI($N$9-$K$9,K14,N14) -> 0.19633171
B15: Gross Profit | D15: =D13+D14 -> 51922.97 | E15: =E13+E14 -> 64900.83 | F15: =F13+F14 -> 155370.63 | G15: =G13+G14 -> 283093 | H15: =H13+H14 -> 326226 | I15: =I13+I14 -> 285571 | J15: =J13+J14 -> 345366.37 | K15: =K13+K14 -> 413005.33 | ... N15: =N13+N14 -> 707148.3 | P15: =IF(OR(I15<=0,N15<=0),"NM",_xlfn.RRI($N$9-$I$9,I15,N15)) -> 0.19883463 | Q15: =IF(OR(K15<=0,N15<=0),"NM",_xlfn.RRI($N$9-$K$9,K15,N15)) -> 0.19633171
B17: Gross Margin % Revenue | D17: =D15/D13 -> 0.35464981 | E17: =E15/E13 -> 0.25028349 | F17: =F15/F13 -> 0.2853641 | G17: =G15/G13 -> 0.41084954 | H17: =H15/H13 -> 0.40373056 | I17: =I15/I13 -> 0.33611654 | J17: =J15/J13 -> 0.34 | K17: =K15/K13 -> 0.34 | ... N17: =N15/N13 -> 0.34
B19: Less: SG&A (Excluding Depreciation and Amortization)
B21: ='Schedule Sheet'!B30 -> Employee Benefit Expenses | D21: ='Schedule Sheet'!D30 -> 32954.92 | E21: ='Schedule Sheet'!E30 -> 34864.43 | F21: ='Schedule Sheet'!F30 -> 47947.52 | G21: ='Schedule Sheet'!G30 -> 64618 | H21: ='Schedule Sheet'!H30 -> 74725 | I21: ='Schedule Sheet'!I30 -> 82722 | J21: ='Schedule Sheet'!J30 -> 101578.34 | K21: ='Schedule Sheet'!K30 -> 121472.16 | ... N21: ='Schedule Sheet'!N30 -> 311977.19 | P21: =IF(OR(I21<=0,N21<=0),"NM",_xlfn.RRI($N$9-$I$9,I21,N21)) -> 0.30406838 | Q21: =IF(OR(K21<=0,N21<=0),"NM",_xlfn.RRI($N$9-$K$9,K21,N21)) -> 0.36945795
B22: ='Schedule Sheet'!B33 -> Other Expenses | D22: ='Schedule Sheet'!D33 -> 19104.1 | E22: ='Schedule Sheet'!E33 -> 24563.07 | F22: ='Schedule Sheet'!F33 -> 42469.61 | G22: ='Schedule Sheet'!G33 -> 55300 | H22: ='Schedule Sheet'!H33 -> 70918 | I22: ='Schedule Sheet'!I33 -> 83015 | J22: ='Schedule Sheet'!J33 -> 91420.509 | K22: ='Schedule Sheet'!K33 -> 109324.94 | ... N22: ='Schedule Sheet'!N33 -> 187186.31 | P22: =IF(OR(I22<=0,N22<=0),"NM",_xlfn.RRI($N$9-$I$9,I22,N22)) -> 0.17658553 | Q22: =IF(OR(K22<=0,N22<=0),"NM",_xlfn.RRI($N$9-$K$9,K22,N22)) -> 0.19633171
B24: Total SG&A | D24: =(D21+D22)*-1 -> -52059.02 | E24: =(E21+E22)*-1 -> -59427.5 | F24: =(F21+F22)*-1 -> -90417.13 | G24: =(G21+G22)*-1 -> -119918 | H24: =(H21+H22)*-1 -> -145643 | I24: =(I21+I22)*-1 -> -165737 | J24: =(J21+J22)*-1 -> -192998.85 | K24: =(K21+K22)*-1 -> -230797.1 | ... N24: =(N21+N22)*-1 -> -499163.5 | P24: =_xlfn.RRI($N$9-$I$9,I24,N24) -> 0.24670778 | Q24: =_xlfn.RRI($N$9-$K$9,K24,N24) -> 0.29321528
B25: EBITDA | D25: =D15+D24 -> -136.05 | E25: =E15+E24 -> 5473.33 | F25: =F15+F24 -> 64953.5 | G25: =G15+G24 -> 163175 | H25: =H15+H24 -> 180583 | I25: =I15+I24 -> 119834 | J25: =J15+J24 -> 152367.51 | K25: =K15+K24 -> 182208.23 | ... N25: =N15+N24 -> 207984.79 | P25: =IF(OR(I25<=0,N25<=0),"NM",_xlfn.RRI($N$9-$I$9,I25,N25)) -> 0.11658118 | Q25: =IF(OR(K25<=0,N25<=0),"NM",_xlfn.RRI($N$9-$K$9,K25,N25)) -> 0.045092012
B27: EBITDA Margin | D27: =D25/D13 -> -0.00092926323 | E27: =E25/E13 -> 0.021107344 | F27: =F25/F13 -> 0.11929795 | G27: =G25/G13 -> 0.23681396 | H27: =H25/H13 -> 0.22348579 | I27: =I25/I13 -> 0.1410444 | J27: =J25/J13 -> 0.15 | K27: =K25/K13 -> 0.15 | ... N27: =N25/N13 -> 0.1
B29: Less: Depreciation and Amortization
B30: Depreciation | D30: ='Income Statement'!J48*-1 -> -46994.46 | E30: ='Income Statement'!K48*-1 -> -50686 | F30: ='Income Statement'!L48*-1 -> -51029.69 | G30: ='Income Statement'!M48*-1 -> -64257 | H30: ='Income Statement'!N48*-1 -> -86802 | I30: ='Income Statement'!O48*-1 -> -108082 | J30: ='Schedule Sheet'!J105*-1 -> -118578.14 | K30: ='Schedule Sheet'!K105*-1 -> -129756.23 | L30: ='Schedule Sheet'!L105*-1 -> -141566.24 | M30: ='Schedule Sheet'!M105*-1 -> -153969.32 | N30: ='Schedule Sheet'!N105*-1 -> -166907.02 | P30: =_xlfn.RRI($N$9-$I$9,I30,N30) -> 0.090797777 | Q30: =_xlfn.RRI($N$9-$K$9,K30,N30) -> 0.087548894
B31: EBIT | D31: =D25+D30 -> -47130.51 | E31: =E25+E30 -> -45212.67 | F31: =F25+F30 -> 13923.81 | G31: =G25+G30 -> 98918 | H31: =H25+H30 -> 93781 | I31: =I25+I30 -> 11752 | J31: =J25+J30 -> 33789.378 | K31: =K25+K30 -> 52452.003 | ... N31: =N25+N30 -> 41077.777 | P31: =IF(OR(I31<=0,N31<=0),"NM",_xlfn.RRI($N$9-$I$9,I31,N31)) -> 0.28439625 | Q31: =IF(OR(K31<=0,N31<=0),"NM",_xlfn.RRI($N$9-$K$9,K31,N31)) -> -0.078246168
B33: EBIT Margin | D33: =D31/D13 -> -0.32191584 | E33: =E31/E13 -> -0.17435809 | F33: =F31/F13 -> 0.025573401 | G33: =G31/G13 -> 0.14355853 | H33: =H31/H13 -> 0.11606143 | I33: =I31/I13 -> 0.013832082 | J33: =J31/J13 -> 0.033264352 | K33: =K31/K13 -> 0.043180269 | ... N33: =N31/N13 -> 0.019750375
B35: Less: Interest Expenses
B36: Finance Cost | D36: ='Income Statement'!J53*-1 -> 21419.83 | E36: ='Income Statement'!K53*-1 -> 23580.15 | F36: ='Income Statement'!L53*-1 -> 31317.31 | G36: ='Income Statement'!M53*-1 -> 41693.54 | H36: ='Income Statement'!N53*-1 -> 50800 | I36: ='Income Statement'!O53*-1 -> 58908 | J36: ='Schedule Sheet'!J234 -> 63865.677 | K36: ='Schedule Sheet'!K234 -> 67999.928 | L36: ='Schedule Sheet'!L234 -> 91529.249 | M36: ='Schedule Sheet'!M234 -> 97716.842 | N36: ='Schedule Sheet'!N234 -> 103612.85 | P36: =IF(OR(I36<=0,N36<=0),"NM",_xlfn.RRI($N$9-$I$9,I36,N36)) -> 0.11956128 | Q36: =IF(OR(K36<=0,N36<=0),"NM",_xlfn.RRI($N$9-$K$9,K36,N36)) -> 0.15071664
B37: Exceptional Items | D37: 0 | E37: 0 | F37: 0 | G37: 0 | H37: 0 | I37: ='Income Statement'!O52*-1 -> 17964 | J37: 0 | K37: 0 | L37: 0 | M37: 0 | N37: 0
B38: Add: Other Income | D38: ='Income Statement'!J51 -> 10369.64 | E38: ='Income Statement'!K51 -> 7255.98 | F38: ='Income Statement'!L51 -> 14349.65 | G38: ='Income Statement'!M51 -> 23269 | H38: ='Income Statement'!N51 -> 32953 | I38: ='Income Statement'!O51 -> 45515 | J38: ='Schedule Sheet'!J240 -> 42662.904 | K38: ='Schedule Sheet'!K240 -> 60736.078 | L38: ='Schedule Sheet'!L240 -> 101705.04 | M38: ='Schedule Sheet'!M240 -> 121673.5 | N38: ='Schedule Sheet'!N240 -> 124790.88 | P38: =IF(OR(I38<=0,N38<=0),"NM",_xlfn.RRI($N$9-$I$9,I38,N38)) -> 0.22350474 | Q38: =IF(OR(K38<=0,N38<=0),"NM",_xlfn.RRI($N$9-$K$9,K38,N38)) -> 0.27129214
B39: EBT | D39: =D31-D36-D37+D38 -> -58180.7 | E39: =E31-E36-E37+E38 -> -61536.84 | F39: =F31-F36-F37+F38 -> -3043.85 | G39: =G31-G36-G37+G38 -> 80493.46 | H39: =H31-H36-H37+H38 -> 75934 | I39: =I31-I36-I37+I38 -> -19605 | J39: =J31-J36-J37+J38 -> 12586.605 | K39: =K31-K36-K37+K38 -> 45188.152 | ... N39: =N31-N36-N37+N38 -> 62255.799 | P39: =IF(OR(I39<=0,N39<=0),"NM",_xlfn.RRI($N$9-$I$9,I39,N39)) -> NM | Q39: =IF(OR(K39<=0,N39<=0),"NM",_xlfn.RRI($N$9-$K$9,K39,N39)) -> 0.1127179
B41: Less: Taxes | D41: ='Income Statement'!J59 -> -116.43 | E41: ='Income Statement'!K59 -> 81.61 | F41: ='Income Statement'!L59 -> 14.04 | G41: ='Income Statement'!M59 -> -1232 | H41: ='Income Statement'!N59 -> 3350 | I41: ='Income Statement'!O59 -> 4331 | J41: ='Schedule Sheet'!J116 -> -3146.6512 | K41: ='Schedule Sheet'!K116 -> -11297.038 | L41: ='Schedule Sheet'!L116 -> -10740.258 | M41: ='Schedule Sheet'!M116 -> -10951.654 | N41: ='Schedule Sheet'!N116 -> -15563.95 | P41: =IF(OR(I41<=0,N41<=0),"NM",_xlfn.RRI($N$9-$I$9,I41,N41)) -> NM | Q41: =_xlfn.RRI($N$9-$K$9,K41,N41) -> 0.1127179
B42: Net Income | D42: =D39-D41 -> -58064.27 | E42: =E39-E41 -> -61618.45 | F42: =F39-F41 -> -3057.89 | G42: =G39-G41 -> 81725.46 | H42: =H39-H41 -> 72584 | I42: =I39-I41 -> -23936 | J42: =J39+J41 -> 9439.9536 | K42: =K39+K41 -> 33891.114 | L42: =L39+L41 -> 32220.774 | M42: =M39+M41 -> 32854.962 | N42: =N39+N41 -> 46691.849 | P42: =IF(OR(I42<=0,N42<=0),"NM",_xlfn.RRI($N$9-$I$9,I42,N42)) -> NM | Q42: =IF(OR(K42<=0,N42<=0),"NM",_xlfn.RRI($N$9-$K$9,K42,N42)) -> 0.1127179
B44: Sales Growth % | D44: =IFERROR(D13/C13-1,"NM") -> NM | E44: =IFERROR(E13/D13-1,"NM") -> 0.77116184 | F44: =IFERROR(F13/E13-1,"NM") -> 1.0996724 | G44: =IFERROR(G13/F13-1,"NM") -> 0.2655425 | H44: =IFERROR(H13/G13-1,"NM") -> 0.17268298 | I44: =IFERROR(I13/H13-1,"NM") -> 0.051470925 | J44: =IFERROR(J13/I13-1,"NM") -> 0.19557523 | K44: =IFERROR(K13/J13-1,"NM") -> 0.19584699 | ... N44: =IFERROR(N13/M13-1,"NM") -> 0.19655765
B45: Gross Profit Margin % | D45: =IFERROR(D15/D13,"NM") -> 0.35464981 | E45: =IFERROR(E15/E13,"NM") -> 0.25028349 | F45: =IFERROR(F15/F13,"NM") -> 0.2853641 | G45: =IFERROR(G15/G13,"NM") -> 0.41084954 | H45: =IFERROR(H15/H13,"NM") -> 0.40373056 | I45: =IFERROR(I15/I13,"NM") -> 0.33611654 | J45: =IFERROR(J15/J13,"NM") -> 0.34 | K45: =IFERROR(K15/K13,"NM") -> 0.34 | ... N45: =IFERROR(N15/N13,"NM") -> 0.34
B46: EBITDA Margin % | D46: =IFERROR(D25/D13,"NM") -> -0.00092926323 | E46: =IFERROR(E25/E13,"NM") -> 0.021107344 | F46: =IFERROR(F25/F13,"NM") -> 0.11929795 | G46: =IFERROR(G25/G13,"NM") -> 0.23681396 | H46: =IFERROR(H25/H13,"NM") -> 0.22348579 | I46: =IFERROR(I25/I13,"NM") -> 0.1410444 | J46: =IFERROR(J25/J13,"NM") -> 0.15 | K46: =IFERROR(K25/K13,"NM") -> 0.15 | ... N46: =IFERROR(N25/N13,"NM") -> 0.1
B47: EBIT Margin % | D47: =IFERROR(D31/D13,"NM") -> -0.32191584 | E47: =IFERROR(E31/E13,"NM") -> -0.17435809 | F47: =IFERROR(F31/F13,"NM") -> 0.025573401 | G47: =IFERROR(G31/G13,"NM") -> 0.14355853 | H47: =IFERROR(H31/H13,"NM") -> 0.11606143 | I47: =IFERROR(I31/I13,"NM") -> 0.013832082 | J47: =IFERROR(J31/J13,"NM") -> 0.033264352 | K47: =IFERROR(K31/K13,"NM") -> 0.043180269 | ... N47: =IFERROR(N31/N13,"NM") -> 0.019750375
B48: Actual Tax Rate % | D48: =IFERROR(-D41/D39,"NM") -> -0.0020011791 | E48: =IFERROR(-E41/E39,"NM") -> 0.0013261974 | F48: =IFERROR(-F41/F39,"NM") -> 0.0046125795 | G48: =IFERROR(-G41/G39,"NM") -> 0.015305591 | H48: =IFERROR(-H41/H39,"NM") -> -0.04411726 | I48: =IFERROR(-I41/I39,"NM") -> 0.22091303 | J48: =IFERROR(-J41/J39,"NM") -> 0.25 | K48: =IFERROR(-K41/K39,"NM") -> 0.25 | ... N48: =IFERROR(-N41/N39,"NM") -> 0.25
B49: Net Income Margin % | D49: =IFERROR(D42/D13,"NM") -> -0.39659677 | E49: =IFERROR(E42/E13,"NM") -> -0.23762533 | F49: =IFERROR(F42/F13,"NM") -> -0.0056163255 | G49: =IFERROR(G42/G13,"NM") -> 0.1186072 | H49: =IFERROR(H42/H13,"NM") -> 0.089828459 | I49: =IFERROR(I42/I13,"NM") -> -0.028172628 | J49: =IFERROR(J42/J13,"NM") -> 0.0092932738 | K49: =IFERROR(K42/K13,"NM") -> 0.027900315 | ... N49: =IFERROR(N42/N13,"NM") -> 0.022449646
B51: Balance Sheet
B53: Assets
B54: Cash | D54: ='Cash Flow Statement'!J95 -> 5088.85 | E54: ='Cash Flow Statement'!K95 -> 10153.29 | F54: ='Cash Flow Statement'!L95 -> 12679.69 | G54: ='Cash Flow Statement'!M95 -> 6953 | H54: ='Cash Flow Statement'!N95 -> 10731 | I54: ='Cash Flow Statement'!O95 -> 13239 | J54: =J202 -> 12850.011 | K54: =K202 -> 75594.011 | L54: =L202 -> 30667.139 | M54: =M202 -> 7441.8579 | N54: =N202 -> 19363.639
B55: Bank balances other than cash and cash equivalents, above | D55: ='Balance Sheet'!J28 -> 107187.8 | E55: ='Balance Sheet'!K28 -> 91048.12 | F55: ='Balance Sheet'!L28 -> 105717.16 | G55: ='Balance Sheet'!M28 -> 160253 | H55: ='Balance Sheet'!N28 -> 178898 | I55: ='Balance Sheet'!O28 -> 226754 | J55: =I55+4292.118555 -> 231046.12 | K55: =J55-591.684659731 -> 230454.43 | L55: =K55+2236.845325515 -> 232691.28 | M55: =L55+831.768270362 -> 233523.05 | N55: =M55+532.783730967 -> 234055.83
B56: Inventory | D56: ='Schedule Sheet'!D140 -> 3164.18 | E56: ='Schedule Sheet'!E140 -> 4080.63 | F56: ='Schedule Sheet'!F140 -> 5910.67 | G56: ='Schedule Sheet'!G140 -> 6248 | H56: ='Schedule Sheet'!H140 -> 8203 | I56: ='Schedule Sheet'!I140 -> 9848 | J56: ='Schedule Sheet'!J140 -> 11020.554 | K56: ='Schedule Sheet'!K140 -> 13178.897 | ... N56: ='Schedule Sheet'!N140 -> 22564.925
B57: Trade Receivables | D57: ='Schedule Sheet'!D134 -> 2189.78 | E57: ='Schedule Sheet'!E134 -> 3329.23 | F57: ='Schedule Sheet'!F134 -> 5199.04 | G57: ='Schedule Sheet'!G134 -> 6425 | H57: ='Schedule Sheet'!H134 -> 7397 | I57: ='Schedule Sheet'!I134 -> 5996 | J57: ='Schedule Sheet'!J134 -> 13914.842 | K57: ='Schedule Sheet'!K134 -> 16640.021 | ... N57: ='Schedule Sheet'!N134 -> 22792.854
...

Sheet Common Sized Model
B2: ='Control Sheet'!B2 -> InterGlobe Aviation
B3: Common Sized Statement Model
H5: Current Case | I5: 1
D7: Actual | J7: Explicit Forecast Period
B8: In INR Crores unless stated otherwise | D8: 2021 | E8: =D8+1 -> 2022 | F8: =E8+1 -> 2023 | G8: =F8+1 -> 2024 | H8: =G8+1 -> 2025 | I8: =H8+1 -> 2026 | J8: =I8+1 -> 2027 | K8: =J8+1 -> 2028 | L8: =K8+1 -> 2029 | ... N8: =M8+1 -> 2031
B10: Common Sized Income Statement
B12: Revenue | D12: ='3 Statement Model'!D13/'3 Statement Model'!D$13 -> 1 | E12: ='3 Statement Model'!E13/'3 Statement Model'!E$13 -> 1 | F12: ='3 Statement Model'!F13/'3 Statement Model'!F$13 -> 1 | G12: ='3 Statement Model'!G13/'3 Statement Model'!G$13 -> 1 | H12: ='3 Statement Model'!H13/'3 Statement Model'!H$13 -> 1 | I12: ='3 Statement Model'!I13/'3 Statement Model'!I$13 -> 1 | J12: ='3 Statement Model'!J13/'3 Statement Model'!J$13 -> 1 | K12: ='3 Statement Model'!K13/'3 Statement Model'!K$13 -> 1 | ... N12: ='3 Statement Model'!N13/'3 Statement Model'!N$13 -> 1
B13: Less: Cost of Goods Sold | D13: ='3 Statement Model'!D14/'3 Statement Model'!D$13 -> -0.64535019 | E13: ='3 Statement Model'!E14/'3 Statement Model'!E$13 -> -0.74971651 | F13: ='3 Statement Model'!F14/'3 Statement Model'!F$13 -> -0.7146359 | G13: ='3 Statement Model'!G14/'3 Statement Model'!G$13 -> -0.58915046 | H13: ='3 Statement Model'!H14/'3 Statement Model'!H$13 -> -0.59626944 | I13: ='3 Statement Model'!I14/'3 Statement Model'!I$13 -> -0.66388346 | J13: ='3 Statement Model'!J14/'3 Statement Model'!J$13 -> -0.66 | K13: ='3 Statement Model'!K14/'3 Statement Model'!K$13 -> -0.66 | ... N13: ='3 Statement Model'!N14/'3 Statement Model'!N$13 -> -0.66
B14: Gross Profit | D14: ='3 Statement Model'!D15/'3 Statement Model'!D$13 -> 0.35464981 | E14: ='3 Statement Model'!E15/'3 Statement Model'!E$13 -> 0.25028349 | F14: ='3 Statement Model'!F15/'3 Statement Model'!F$13 -> 0.2853641 | G14: ='3 Statement Model'!G15/'3 Statement Model'!G$13 -> 0.41084954 | H14: ='3 Statement Model'!H15/'3 Statement Model'!H$13 -> 0.40373056 | I14: ='3 Statement Model'!I15/'3 Statement Model'!I$13 -> 0.33611654 | J14: ='3 Statement Model'!J15/'3 Statement Model'!J$13 -> 0.34 | K14: ='3 Statement Model'!K15/'3 Statement Model'!K$13 -> 0.34 | ... N14: ='3 Statement Model'!N15/'3 Statement Model'!N$13 -> 0.34
B16: Less: SG&A (Excluding Depreciation and Amortization)
B17: ='3 Statement Model'!B21 -> Employee Benefit Expenses | D17: ='3 Statement Model'!D21/'3 Statement Model'!D$13 -> 0.22509221 | E17: ='3 Statement Model'!E21/'3 Statement Model'!E$13 -> 0.13445115 | F17: ='3 Statement Model'!F21/'3 Statement Model'!F$13 -> 0.088063625 | G17: ='3 Statement Model'!G21/'3 Statement Model'!G$13 -> 0.093779343 | H17: ='3 Statement Model'!H21/'3 Statement Model'!H$13 -> 0.092478117 | I17: ='3 Statement Model'!I21/'3 Statement Model'!I$13 -> 0.097363642 | J17: ='3 Statement Model'!J21/'3 Statement Model'!J$13 -> 0.1 | K17: ='3 Statement Model'!K21/'3 Statement Model'!K$13 -> 0.1 | ... N17: ='3 Statement Model'!N21/'3 Statement Model'!N$13 -> 0.15
B18: ='3 Statement Model'!B22 -> Other Expenses | D18: ='3 Statement Model'!D22/'3 Statement Model'!D$13 -> 0.13048686 | E18: ='3 Statement Model'!E22/'3 Statement Model'!E$13 -> 0.094724998 | F18: ='3 Statement Model'!F22/'3 Statement Model'!F$13 -> 0.078002528 | G18: ='3 Statement Model'!G22/'3 Statement Model'!G$13 -> 0.080256239 | H18: ='3 Statement Model'!H22/'3 Statement Model'!H$13 -> 0.087766652 | I18: ='3 Statement Model'!I22/'3 Statement Model'!I$13 -> 0.097708502 | J18: ='3 Statement Model'!J22/'3 Statement Model'!J$13 -> 0.09 | K18: ='3 Statement Model'!K22/'3 Statement Model'!K$13 -> 0.09 | ... N18: ='3 Statement Model'!N22/'3 Statement Model'!N$13 -> 0.09
B20: ='3 Statement Model'!B24 -> Total SG&A | D20: ='3 Statement Model'!D24/'3 Statement Model'!D$13 -> -0.35557907 | E20: ='3 Statement Model'!E24/'3 Statement Model'!E$13 -> -0.22917615 | F20: ='3 Statement Model'!F24/'3 Statement Model'!F$13 -> -0.16606615 | G20: ='3 Statement Model'!G24/'3 Statement Model'!G$13 -> -0.17403558 | H20: ='3 Statement Model'!H24/'3 Statement Model'!H$13 -> -0.18024477 | I20: ='3 Statement Model'!I24/'3 Statement Model'!I$13 -> -0.19507214 | J20: ='3 Statement Model'!J24/'3 Statement Model'!J$13 -> -0.19 | K20: ='3 Statement Model'!K24/'3 Statement Model'!K$13 -> -0.19 | ... N20: ='3 Statement Model'!N24/'3 Statement Model'!N$13 -> -0.24
B21: ='3 Statement Model'!B25 -> EBITDA | D21: ='3 Statement Model'!D25/'3 Statement Model'!D$13 -> -0.00092926323 | E21: ='3 Statement Model'!E25/'3 Statement Model'!E$13 -> 0.021107344 | F21: ='3 Statement Model'!F25/'3 Statement Model'!F$13 -> 0.11929795 | G21: ='3 Statement Model'!G25/'3 Statement Model'!G$13 -> 0.23681396 | H21: ='3 Statement Model'!H25/'3 Statement Model'!H$13 -> 0.22348579 | I21: ='3 Statement Model'!I25/'3 Statement Model'!I$13 -> 0.1410444 | J21: ='3 Statement Model'!J25/'3 Statement Model'!J$13 -> 0.15 | K21: ='3 Statement Model'!K25/'3 Statement Model'!K$13 -> 0.15 | ... N21: ='3 Statement Model'!N25/'3 Statement Model'!N$13 -> 0.1
B23: ='3 Statement Model'!B29 -> Less: Depreciation and Amortization
B24: ='3 Statement Model'!B30 -> Depreciation | D24: ='3 Statement Model'!D30/'3 Statement Model'!D$13 -> -0.32098657 | E24: ='3 Statement Model'!E30/'3 Statement Model'!E$13 -> -0.19546544 | F24: ='3 Statement Model'!F30/'3 Statement Model'!F$13 -> -0.093724544 | G24: ='3 Statement Model'!G30/'3 Statement Model'!G$13 -> -0.093255428 | H24: ='3 Statement Model'!H30/'3 Statement Model'!H$13 -> -0.10742436 | I24: ='3 Statement Model'!I30/'3 Statement Model'!I$13 -> -0.12721232 | J24: ='3 Statement Model'!J30/'3 Statement Model'!J$13 -> -0.11673565 | K24: ='3 Statement Model'!K30/'3 Statement Model'!K$13 -> -0.10681973 | ... N24: ='3 Statement Model'!N30/'3 Statement Model'!N$13 -> -0.080249625
B25: ='3 Statement Model'!B31 -> EBIT | D25: ='3 Statement Model'!D31/'3 Statement Model'!D$13 -> -0.32191584 | E25: ='3 Statement Model'!E31/'3 Statement Model'!E$13 -> -0.17435809 | F25: ='3 Statement Model'!F31/'3 Statement Model'!F$13 -> 0.025573401 | G25: ='3 Statement Model'!G31/'3 Statement Model'!G$13 -> 0.14355853 | H25: ='3 Statement Model'!H31/'3 Statement Model'!H$13 -> 0.11606143 | I25: ='3 Statement Model'!I31/'3 Statement Model'!I$13 -> 0.013832082 | J25: ='3 Statement Model'!J31/'3 Statement Model'!J$13 -> 0.033264352 | K25: ='3 Statement Model'!K31/'3 Statement Model'!K$13 -> 0.043180269 | ... N25: ='3 Statement Model'!N31/'3 Statement Model'!N$13 -> 0.019750375
B27: ='3 Statement Model'!B35 -> Less: Interest Expenses
B28: ='3 Statement Model'!B36 -> Finance Cost | D28: ='3 Statement Model'!D36/'3 Statement Model'!D$13*-1 -> -0.14630401 | E28: ='3 Statement Model'!E36/'3 Statement Model'!E$13*-1 -> -0.090934466 | F28: ='3 Statement Model'!F36/'3 Statement Model'!F$13*-1 -> -0.057519468 | G28: ='3 Statement Model'!G36/'3 Statement Model'!G$13*-1 -> -0.060509344 | H28: ='3 Statement Model'!H36/'3 Statement Model'!H$13*-1 -> -0.062869031 | I28: ='3 Statement Model'!I36/'3 Statement Model'!I$13*-1 -> -0.069334608 | J28: ='3 Statement Model'!J36/'3 Statement Model'!J$13*-1 -> -0.062873321 | K28: ='3 Statement Model'!K36/'3 Statement Model'!K$13*-1 -> -0.055979848 | ... N28: ='3 Statement Model'!N36/'3 Statement Model'!N$13*-1 -> -0.049817514
B29: ='3 Statement Model'!B37 -> Exceptional Items | D29: ='3 Statement Model'!D37/'3 Statement Model'!D$13*-1 -> 0 | E29: ='3 Statement Model'!E37/'3 Statement Model'!E$13*-1 -> 0 | F29: ='3 Statement Model'!F37/'3 Statement Model'!F$13*-1 -> 0 | G29: ='3 Statement Model'!G37/'3 Statement Model'!G$13*-1 -> 0 | H29: ='3 Statement Model'!H37/'3 Statement Model'!H$13*-1 -> 0 | I29: ='3 Statement Model'!I37/'3 Statement Model'!I$13*-1 -> -0.021143595 | J29: ='3 Statement Model'!J37/'3 Statement Model'!J$13*-1 -> 0 | K29: ='3 Statement Model'!K37/'3 Statement Model'!K$13*-1 -> 0 | ... N29: ='3 Statement Model'!N37/'3 Statement Model'!N$13*-1 -> 0
B30: ='3 Statement Model'!B38 -> Add: Other Income | D30: ='3 Statement Model'!D38/'3 Statement Model'!D$13 -> 0.070827822 | E30: ='3 Statement Model'!E38/'3 Statement Model'!E$13 -> 0.027981954 | F30: ='3 Statement Model'!F38/'3 Statement Model'!F$13 -> 0.026355528 | G30: ='3 Statement Model'!G38/'3 Statement Model'!G$13 -> 0.033770026 | H30: ='3 Statement Model'!H38/'3 Statement Model'!H$13 -> 0.040781952 | I30: ='3 Statement Model'!I38/'3 Statement Model'!I$13 -> 0.053571071 | J30: ='3 Statement Model'!J38/'3 Statement Model'!J$13 -> 0.042 | K30: ='3 Statement Model'!K38/'3 Statement Model'!K$13 -> 0.05 | ... N30: ='3 Statement Model'!N38/'3 Statement Model'!N$13 -> 0.06
B31: ='3 Statement Model'!B39 -> EBT | D31: ='3 Statement Model'!D39/'3 Statement Model'!D$13 -> -0.39739202 | E31: ='3 Statement Model'!E39/'3 Statement Model'!E$13 -> -0.23731061 | F31: ='3 Statement Model'!F39/'3 Statement Model'!F$13 -> -0.0055905387 | G31: ='3 Statement Model'!G39/'3 Statement Model'!G$13 -> 0.11681921 | H31: ='3 Statement Model'!H39/'3 Statement Model'!H$13 -> 0.09397435 | I31: ='3 Statement Model'!I39/'3 Statement Model'!I$13 -> -0.023075049 | J31: ='3 Statement Model'!J39/'3 Statement Model'!J$13 -> 0.012391032 | K31: ='3 Statement Model'!K39/'3 Statement Model'!K$13 -> 0.03720042 | ... N31: ='3 Statement Model'!N39/'3 Statement Model'!N$13 -> 0.029932861
B33: ='3 Statement Model'!B41 -> Less: Taxes | D33: ='3 Statement Model'!D41/'3 Statement Model'!D$13 -> -0.00079525261 | E33: ='3 Statement Model'!E41/'3 Statement Model'!E$13 -> 0.00031472072 | F33: ='3 Statement Model'!F41/'3 Statement Model'!F$13 -> 2.5786804e-05 | G33: ='3 Statement Model'!G41/'3 Statement Model'!G$13 -> -0.0017879871 | H33: ='3 Statement Model'!H41/'3 Statement Model'!H$13 -> 0.0041458908 | I33: ='3 Statement Model'!I41/'3 Statement Model'!I$13 -> 0.005097579 | J33: ='3 Statement Model'!J41/'3 Statement Model'!J$13 -> -0.0030977579 | K33: ='3 Statement Model'!K41/'3 Statement Model'!K$13 -> -0.0093001051 | ... N33: ='3 Statement Model'!N41/'3 Statement Model'!N$13 -> -0.0074832152
B34: ='3 Statement Model'!B42 -> Net Income | D34: ='3 Statement Model'!D42/'3 Statement Model'!D$13 -> -0.39659677 | E34: ='3 Statement Model'!E42/'3 Statement Model'!E$13 -> -0.23762533 | F34: ='3 Statement Model'!F42/'3 Statement Model'!F$13 -> -0.0056163255 | G34: ='3 Statement Model'!G42/'3 Statement Model'!G$13 -> 0.1186072 | H34: ='3 Statement Model'!H42/'3 Statement Model'!H$13 -> 0.089828459 | I34: ='3 Statement Model'!I42/'3 Statement Model'!I$13 -> -0.028172628 | J34: ='3 Statement Model'!J42/'3 Statement Model'!J$13 -> 0.0092932738 | K34: ='3 Statement Model'!K42/'3 Statement Model'!K$13 -> 0.027900315 | ... N34: ='3 Statement Model'!N42/'3 Statement Model'!N$13 -> 0.022449646
B36: ='3 Statement Model'!B51 -> Balance Sheet
B38: ='3 Statement Model'!B53 -> Assets
B39: ='3 Statement Model'!B54 -> Cash | D39: ='3 Statement Model'!D54/'3 Statement Model'!D$74 -> 0.011820473 | E39: ='3 Statement Model'!E54/'3 Statement Model'!E$74 -> 0.022090331 | F39: ='3 Statement Model'!F54/'3 Statement Model'!F$74 -> 0.02142932 | G39: ='3 Statement Model'!G54/'3 Statement Model'!G$74 -> 0.0084561171 | H39: ='3 Statement Model'!H54/'3 Statement Model'!H$74 -> 0.0092633596 | I39: ='3 Statement Model'!I54/'3 Statement Model'!I$74 -> 0.0097344085 | J39: ='3 Statement Model'!J54/'3 Statement Model'!J$74 -> 0.0085840622 | K39: ='3 Statement Model'!K54/'3 Statement Model'!K$74 -> 0.044499139 | ... N39: ='3 Statement Model'!N54/'3 Statement Model'!N$74 -> 0.0089490808
B40: ='3 Statement Model'!B55 -> Bank balances other than cash and cash equivalents, above | D40: ='3 Statement Model'!D55/'3 Statement Model'!D$74 -> 0.24897777 | E40: ='3 Statement Model'!E55/'3 Statement Model'!E$74 -> 0.19809176 | F40: ='3 Statement Model'!F55/'3 Statement Model'!F$74 -> 0.17866737 | G40: ='3 Statement Model'!G55/'3 Statement Model'!G$74 -> 0.1948969 | H40: ='3 Statement Model'!H55/'3 Statement Model'!H$74 -> 0.15443076 | I40: ='3 Statement Model'!I55/'3 Statement Model'!I$74 -> 0.16672831 | J40: ='3 Statement Model'!J55/'3 Statement Model'!J$74 -> 0.15434339 | K40: ='3 Statement Model'!K55/'3 Statement Model'!K$74 -> 0.13565921 | ... N40: ='3 Statement Model'!N55/'3 Statement Model'!N$74 -> 0.10817102
B41: ='3 Statement Model'!B56 -> Inventory | D41: ='3 Statement Model'!D56/'3 Statement Model'!D$74 -> 0.0073498148 | E41: ='3 Statement Model'!E56/'3 Statement Model'!E$74 -> 0.0088781535 | F41: ='3 Statement Model'!F56/'3 Statement Model'!F$74 -> 0.0099893326 | G41: ='3 Statement Model'!G56/'3 Statement Model'!G$74 -> 0.0075987084 | H41: ='3 Statement Model'!H56/'3 Statement Model'!H$74 -> 0.0070811051 | I41: ='3 Statement Model'!I56/'3 Statement Model'!I$74 -> 0.0072410647 | J41: ='3 Statement Model'!J56/'3 Statement Model'!J$74 -> 0.0073619491 | K41: ='3 Statement Model'!K56/'3 Statement Model'!K$74 -> 0.0077578839 | ... N41: ='3 Statement Model'!N56/'3 Statement Model'!N$74 -> 0.010428584
B42: ='3 Statement Model'!B57 -> Trade Receivables | D42: ='3 Statement Model'!D57/'3 Statement Model'!D$74 -> 0.0050864608 | E42: ='3 Statement Model'!E57/'3 Statement Model'!E$74 -> 0.007243346 | F42: ='3 Statement Model'!F57/'3 Statement Model'!F$74 -> 0.0087866417 | G42: ='3 Statement Model'!G57/'3 Statement Model'!G$74 -> 0.0078139727 | H42: ='3 Statement Model'!H57/'3 Statement Model'!H$74 -> 0.0063853388 | I42: ='3 Statement Model'!I57/'3 Statement Model'!I$74 -> 0.0044087555 | J42: ='3 Statement Model'!J57/'3 Statement Model'!J$74 -> 0.0092953903 | K42: ='3 Statement Model'!K57/'3 Statement Model'!K$74 -> 0.009795308 | ... N42: ='3 Statement Model'!N57/'3 Statement Model'!N$74 -> 0.010533924
B43: ='3 Statement Model'!B58 -> Prepaid Expenses | D43: ='3 Statement Model'!D58/'3 Statement Model'!D$74 -> 0.0009080593 | E43: ='3 Statement Model'!E58/'3 Statement Model'!E$74 -> 0.0013758578 | F43: ='3 Statement Model'!F58/'3 Statement Model'!F$74 -> 0.0011318777 | G43: ='3 Statement Model'!G58/'3 Statement Model'!G$74 -> 0.0012514518 | H43: ='3 Statement Model'!H58/'3 Statement Model'!H$74 -> 0.0018455934 | I43: ='3 Statement Model'!I58/'3 Statement Model'!I$74 -> 0.0024992261 | J43: ='3 Statement Model'!J58/'3 Statement Model'!J$74 -> 0.0031349633 | K43: ='3 Statement Model'!K58/'3 Statement Model'!K$74 -> 0.0033035656 | ... N43: ='3 Statement Model'!N58/'3 Statement Model'!N$74 -> 0.0044408388
B44: ='3 Statement Model'!B59 -> Financial Current Assets | D44: ='3 Statement Model'!D59/'3 Statement Model'!D$74 -> 0.18785318 | E44: ='3 Statement Model'!E59/'3 Statement Model'!E$74 -> 0.18350969 | F44: ='3 Statement Model'!F59/'3 Statement Model'!F$74 -> 0.21290915 | G44: ='3 Statement Model'!G59/'3 Statement Model'!G$74 -> 0.21039106 | H44: ='3 Statement Model'!H59/'3 Statement Model'!H$74 -> 0.24482599 | I44: ='3 Statement Model'!I59/'3 Statement Model'!I$74 -> 0.22454433 | J44: ='3 Statement Model'!J59/'3 Statement Model'!J$74 -> 0.23749722 | K44: ='3 Statement Model'!K59/'3 Statement Model'!K$74 -> 0.25027012 | ... N44: ='3 Statement Model'!N59/'3 Statement Model'!N$74 -> 0.33642718
B45: ='3 Statement Model'!B60 -> Other Current Assets | D45: ='3 Statement Model'!D60/'3 Statement Model'!D$74 -> 0.021473687 | E45: ='3 Statement Model'!E60/'3 Statement Model'!E$74 -> 0.018926954 | F45: ='3 Statement Model'!F60/'3 Statement Model'!F$74 -> 0.009012855 | G45: ='3 Statement Model'!G60/'3 Statement Model'!G$74 -> 0.0056309251 | H45: ='3 Statement Model'!H60/'3 Statement Model'!H$74 -> 0.013854036 | I45: ='3 Statement Model'!I60/'3 Statement Model'!I$74 -> 0.010787333 | J45: ='3 Statement Model'!J60/'3 Statement Model'!J$74 -> 0.020356905 | K45: ='3 Statement Model'!K60/'3 Statement Model'!K$74 -> 0.021451724 | ... N45: ='3 Statement Model'!N60/'3 Statement Model'!N$74 -> 0.028836616
B46: ='3 Statement Model'!B61 -> Total Current Assests | D46: ='3 Statement Model'!D61/'3 Statement Model'!D$74 -> 0.48346944 | E46: ='3 Statement Model'!E61/'3 Statement Model'!E$74 -> 0.44011609 | F46: ='3 Statement Model'!F61/'3 Statement Model'!F$74 -> 0.44192655 | G46: ='3 Statement Model'!G61/'3 Statement Model'!G$74 -> 0.43603914 | H46: ='3 Statement Model'!H61/'3 Statement Model'!H$74 -> 0.43768619 | I46: ='3 Statement Model'!I61/'3 Statement Model'!I$74 -> 0.42594342 | J46: ='3 Statement Model'!J61/'3 Statement Model'!J$74 -> 0.44057388 | K46: ='3 Statement Model'!K61/'3 Statement Model'!K$74 -> 0.47273695 | ... N46: ='3 Statement Model'!N61/'3 Statement Model'!N$74 -> 0.50778724
B48: ='3 Statement Model'!B63 -> Plant, Machinery and Equipment | D48: ='3 Statement Model'!D63/'3 Statement Model'!D$74 -> 0.018512071 | E48: ='3 Statement Model'!E63/'3 Statement Model'!E$74 -> 0.017926598 | F48: ='3 Statement Model'!F63/'3 Statement Model'!F$74 -> 0.018779321 | G48: ='3 Statement Model'!G63/'3 Statement Model'!G$74 -> 0.023142737 | H48: ='3 Statement Model'!H63/'3 Statement Model'!H$74 -> 0.023116532 | I48: ='3 Statement Model'!I63/'3 Statement Model'!I$74 -> 0.081521535 | J48: ='3 Statement Model'!J63/'3 Statement Model'!J$74 -> 0.078670911 | K48: ='3 Statement Model'!K63/'3 Statement Model'!K$74 -> 0.073243935 | ... N48: ='3 Statement Model'!N63/'3 Statement Model'!N$74 -> 0.065198846
B49: ='3 Statement Model'!B64 -> Right of use assets | D49: ='3 Statement Model'!D64/'3 Statement Model'!D$74 -> 0.41778605 | E49: ='3 Statement Model'!E64/'3 Statement Model'!E$74 -> 0.44466912 | F49: ='3 Statement Model'!F64/'3 Statement Model'!F$74 -> 0.44848025 | G49: ='3 Statement Model'!G64/'3 Statement Model'!G$74 -> 0.4159624 | H49: ='3 Statement Model'!H64/'3 Statement Model'!H$74 -> 0.42362239 | I49: ='3 Statement Model'!I64/'3 Statement Model'!I$74 -> 0.38274409 | J49: ='3 Statement Model'!J64/'3 Statement Model'!J$74 -> 0.36936039 | K49: ='3 Statement Model'!K64/'3 Statement Model'!K$74 -> 0.34388071 | ... N49: ='3 Statement Model'!N64/'3 Statement Model'!N$74 -> 0.30610897
B50: ='3 Statement Model'!B65 -> Capital Work In Progress | D50: ='3 Statement Model'!D65/'3 Statement Model'!D$74 -> 0.0015412131 | E50: ='3 Statement Model'!E65/'3 Statement Model'!E$74 -> 0.0025959803 | F50: ='3 Statement Model'!F65/'3 Statement Model'!F$74 -> 0 | G50: ='3 Statement Model'!G65/'3 Statement Model'!G$74 -> 1.2161825e-06 | H50: ='3 Statement Model'!H65/'3 Statement Model'!H$74 -> 6.0426351e-06 | I50: ='3 Statement Model'!I65/'3 Statement Model'!I$74 -> 0.00028455443 | J50: ='3 Statement Model'!J65/'3 Statement Model'!J$74 -> 0 | K50: ='3 Statement Model'!K65/'3 Statement Model'!K$74 -> 0 | ... N50: ='3 Statement Model'!N65/'3 Statement Model'!N$74 -> 0
B51: ='3 Statement Model'!B66 -> Other Non-Current Assets | D51: ='3 Statement Model'!D66/'3 Statement Model'!D$74 -> 0.022062429 | E51: ='3 Statement Model'!E66/'3 Statement Model'!E$74 -> 0.02668907 | F51: ='3 Statement Model'!F66/'3 Statement Model'!F$74 -> 0.025302291 | G51: ='3 Statement Model'!G66/'3 Statement Model'!G$74 -> 0.023303273 | H51: ='3 Statement Model'!H66/'3 Statement Model'!H$74 -> 0.020863493 | I51: ='3 Statement Model'!I66/'3 Statement Model'!I$74 -> 0.028215006 | J51: ='3 Statement Model'!J66/'3 Statement Model'!J$74 -> 0.028197318 | K51: ='3 Statement Model'!K66/'3 Statement Model'!K$74 -> 0.027332247 | ... N51: ='3 Statement Model'!N66/'3 Statement Model'!N$74 -> 0.028561475
... B59: ='3 Statement Model'!B74 -> Total Assets | D59: ='3 Statement Model'!D74/'3 Statement Model'!D$74 -> 1 | E59: ='3 Statement Model'!E74/'3 Statement Model'!E$74 -> 1 | F59: ='3 Statement Model'!F74/'3 Statement Model'!F$74 -> 1 | G59: ='3 Statement Model'!G74/'3 Statement Model'!G$74 -> 1 | H59: ='3 Statement Model'!H74/'3 Statement Model'!H$74 -> 1 | I59: ='3 Statement Model'!I74/'3 Statement Model'!I$74 -> 1 | J59: ='3 Statement Model'!J74/'3 Statement Model'!J$74 -> 1 | K59: ='3 Statement Model'!K74/'3 Statement Model'!K$74 -> 1 | ... N59: ='3 Statement Model'!N74/'3 Statement Model'!N$74 -> 1
B62: ='3 Statement Model'!B77 -> Liability and Shareholder's Equity
...

Sheet Ratio Analysis
B2: ='Control Sheet'!B2 -> InterGlobe Aviation
B3: Ratio Analysis
H5: Current Case | I5: 1
D8: Actual | E8: Actual | K8: Explicit Forecast Period
B9: In INR Crores unless stated otherwise | E9: 2021 | F9: =E9+1 -> 2022 | G9: =F9+1 -> 2023 | H9: =G9+1 -> 2024 | I9: =H9+1 -> 2025 | J9: =I9+1 -> 2026 | K9: =J9+1 -> 2027 | L9: =K9+1 -> 2028 | M9: =L9+1 -> 2029 | ... O9: =N9+1 -> 2031
B11: Liquidity Ratio
B13: Current Assets | E13: ='3 Statement Model'!D61 -> 208139.17 | F13: ='3 Statement Model'!E61 -> 202288.79 | G13: ='3 Statement Model'!F61 -> 261487.14 | H13: ='3 Statement Model'!G61 -> 358531 | I13: ='3 Statement Model'!H61 -> 507031 | J13: ='3 Statement Model'!I61 -> 579292 | K13: ='3 Statement Model'!J61 -> 659522.15 | L13: ='3 Statement Model'!K61 -> 803073.57 | ... O13: ='3 Statement Model'!N61 -> 1098728.4
B14: Current Liability | E14: ='3 Statement Model'!D85 -> 189236.92 | F14: ='3 Statement Model'!E85 -> 224171.4 | G14: ='3 Statement Model'!F85 -> 238511.46 | H14: ='3 Statement Model'!G85 -> 307982 | I14: ='3 Statement Model'!H85 -> 342178 | J14: ='3 Statement Model'!I85 -> 382710 | K14: ='3 Statement Model'!J85 -> 415715.16 | L14: ='3 Statement Model'!K85 -> 485944.6 | ... O14: ='3 Statement Model'!N85 -> 724452.04
B15: Liquidity Ratio | E15: =E13/E14 -> 1.0998867 | F15: =F13/F14 -> 0.90238447 | G15: =G13/G14 -> 1.0963295 | H15: =H13/H14 -> 1.1641297 | I15: =I13/I14 -> 1.4817756 | J15: =J13/J14 -> 1.5136579 | K15: =K13/K14 -> 1.586476 | L15: =L13/L14 -> 1.6526031 | ... O15: =O13/O14 -> 1.5166337
B17: Current Assets | E17: ='3 Statement Model'!D61 -> 208139.17 | F17: ='3 Statement Model'!E61 -> 202288.79 | G17: ='3 Statement Model'!F61 -> 261487.14 | H17: ='3 Statement Model'!G61 -> 358531 | I17: ='3 Statement Model'!H61 -> 507031 | J17: ='3 Statement Model'!I61 -> 579292 | K17: ='3 Statement Model'!J61 -> 659522.15 | L17: ='3 Statement Model'!K61 -> 803073.57 | ... O17: ='3 Statement Model'!N61 -> 1098728.4
B18: Inventory | E18: ='3 Statement Model'!D56 -> 3164.18 | F18: ='3 Statement Model'!E56 -> 4080.63 | G18: ='3 Statement Model'!F56 -> 5910.67 | H18: ='3 Statement Model'!G56 -> 6248 | I18: ='3 Statement Model'!H56 -> 8203 | J18: ='3 Statement Model'!I56 -> 9848 | K18: ='3 Statement Model'!J56 -> 11020.554 | L18: ='3 Statement Model'!K56 -> 13178.897 | ... O18: ='3 Statement Model'!N56 -> 22564.925
B19: Prepaid Expenses | E19: ='3 Statement Model'!D58 -> 390.93 | F19: ='3 Statement Model'!E58 -> 632.38 | G19: ='3 Statement Model'!F58 -> 669.73 | H19: ='3 Statement Model'!G58 -> 1029 | I19: ='3 Statement Model'!H58 -> 2138 | J19: ='3 Statement Model'!I58 -> 3399 | K19: ='3 Statement Model'!J58 -> 4692.9194 | L19: ='3 Statement Model'!K58 -> 5612.0136 | ... O19: ='3 Statement Model'!N58 -> 9608.8974
B20: Current Liability | E20: ='3 Statement Model'!D85 -> 189236.92 | F20: ='3 Statement Model'!E85 -> 224171.4 | G20: ='3 Statement Model'!F85 -> 238511.46 | H20: ='3 Statement Model'!G85 -> 307982 | I20: ='3 Statement Model'!H85 -> 342178 | J20: ='3 Statement Model'!I85 -> 382710 | K20: ='3 Statement Model'!J85 -> 415715.16 | L20: ='3 Statement Model'!K85 -> 485944.6 | ... O20: ='3 Statement Model'!N85 -> 724452.04
B21: Quick Ratio (Acid Ratio) | E21: =(E17-E18-E19)/E20 -> 1.0811001 | F21: =(F17-F18-F19)/F20 -> 0.88136033 | G21: =(G17-G18-G19)/G20 -> 1.06874 | H21: =(H17-H18-H19)/H20 -> 1.1405017 | I21: =(I17-I18-I19)/I20 -> 1.4515545 | J21: =(J17-J18-J19)/J20 -> 1.4790442 | K21: =(K17-K18-K19)/K20 -> 1.5486774 | L21: =(L17-L18-L19)/L20 -> 1.6139343 | ... O21: =(O17-O18-O19)/O20 -> 1.4722224
B23: Inventory Days | E23: ='Schedule Sheet'!D141 -> 12.223591 | F23: ='Schedule Sheet'!E141 -> 7.6613441 | G23: ='Schedule Sheet'!F141 -> 5.544663 | H23: ='Schedule Sheet'!G141 -> 5.6177362 | I23: ='Schedule Sheet'!H141 -> 6.2143552 | J23: ='Schedule Sheet'!I141 -> 4 | K23: ='Schedule Sheet'!J141 -> 6 | L23: ='Schedule Sheet'!K141 -> 6 | ... O23: ='Schedule Sheet'!N141 -> 6
B24: Debtor Days | E24: ='Schedule Sheet'!D135 -> 5.4592572 | F24: ='Schedule Sheet'!E135 -> 4.6861763 | G24: ='Schedule Sheet'!F135 -> 3.4853503 | H24: ='Schedule Sheet'!G135 -> 3.4034523 | I24: ='Schedule Sheet'!H135 -> 3.3413467 | J24: ='Schedule Sheet'!I135 -> 5 | K24: ='Schedule Sheet'!J135 -> 5 | L24: ='Schedule Sheet'!K135 -> 5 | ... O24: ='Schedule Sheet'!N135 -> 4
B25: Creditor Days | E25: ='Schedule Sheet'!D162 -> 59.929622 | F25: ='Schedule Sheet'!E162 -> 59.175121 | G25: ='Schedule Sheet'!F162 -> 30.102785 | H25: ='Schedule Sheet'!G162 -> 28.390787 | I25: ='Schedule Sheet'!H162 -> 31.633136 | J25: ='Schedule Sheet'!I162 -> 32.293927 | K25: ='Schedule Sheet'!J162 -> 30 | L25: ='Schedule Sheet'!K162 -> 30 | ... O25: ='Schedule Sheet'!N162 -> 25
B26: Cash Conversion Days | E26: =E23+E24-E25 -> -42.246774 | F26: =F23+F24-F25 -> -46.827601 | G26: =G23+G24-G25 -> -21.072771 | H26: =H23+H24-H25 -> -19.369599 | I26: =I23+I24-I25 -> -22.077434 | J26: =J23+J24-J25 -> -23.293927 | K26: =K23+K24-K25 -> -19 | L26: =L23+L24-L25 -> -19 | ... O26: =O23+O24-O25 -> -15
B28: Leverage Ratios (Solvency Ratios)
B30: Total Debt | E30: ='3 Statement Model'!D87+'3 Statement Model'!D81 -> 298596.54 | F30: ='3 Statement Model'!E87+'3 Statement Model'!E81 -> 368778.37 | G30: ='3 Statement Model'!F87+'3 Statement Model'!F81 -> 448542.13 | H30: ='3 Statement Model'!G87+'3 Statement Model'!G81 -> 512801 | I30: ='3 Statement Model'!H87+'3 Statement Model'!H81 -> 668098 | J30: ='3 Statement Model'!I87+'3 Statement Model'!I81 -> 777492 | K30: ='3 Statement Model'!J87+'3 Statement Model'!J81 -> 819149.93 | L30: ='3 Statement Model'!K87+'3 Statement Model'!K81 -> 880848.28 | ... O30: ='3 Statement Model'!N87+'3 Statement Model'!N81 -> 1067656.9
B31: Total Equity | E31: ='3 Statement Model'!D95+'3 Statement Model'!D96 -> 1108.59 | F31: ='3 Statement Model'!E95+'3 Statement Model'!E96 -> -59880.62 | G31: ='3 Statement Model'!F95+'3 Statement Model'!F96 -> -62465.16 | H31: ='3 Statement Model'!G95+'3 Statement Model'!G96 -> 19965 | I31: ='3 Statement Model'!H95+'3 Statement Model'!H96 -> 93682 | J31: ='3 Statement Model'!I95+'3 Statement Model'!I96 -> 69711 | K31: ='3 Statement Model'!J95+'3 Statement Model'!J96 -> 79150.954 | L31: ='3 Statement Model'!K95+'3 Statement Model'!K96 -> 113042.07 | ... O31: ='3 Statement Model'!N95+'3 Statement Model'!N96 -> 224809.65
B32: Debt to Equity | E32: =E30/E31 -> 269.34804 | F32: =F30/F31 -> -6.1585596 | G32: =G30/G31 -> -7.1806769 | H32: =H30/H31 -> 25.684999 | I32: =I30/I31 -> 7.1315514 | J32: =J30/J31 -> 11.153075 | K32: =K30/K31 -> 10.349211 | L32: =L30/L31 -> 7.7922166 | ... O32: =O30/O31 -> 4.7491597
B34: Total Debt | E34: ='3 Statement Model'!D87+'3 Statement Model'!D81 -> 298596.54 | F34: ='3 Statement Model'!E87+'3 Statement Model'!E81 -> 368778.37 | G34: ='3 Statement Model'!F87+'3 Statement Model'!F81 -> 448542.13 | H34: ='3 Statement Model'!G87+'3 Statement Model'!G81 -> 512801 | I34: ='3 Statement Model'!H87+'3 Statement Model'!H81 -> 668098 | J34: ='3 Statement Model'!I87+'3 Statement Model'!I81 -> 777492 | K34: ='3 Statement Model'!J87+'3 Statement Model'!J81 -> 819149.93 | L34: ='3 Statement Model'!K87+'3 Statement Model'!K81 -> 880848.28 | ... O34: ='3 Statement Model'!N87+'3 Statement Model'!N81 -> 1067656.9
B35: Total Assets | E35: ='3 Statement Model'!D74 -> 430511.53 | F35: ='3 Statement Model'!E74 -> 459625.98 | G35: ='3 Statement Model'!F74 -> 591698.19 | H35: ='3 Statement Model'!G74 -> 822245 | I35: ='3 Statement Model'!H74 -> 1158435 | J35: ='3 Statement Model'!I74 -> 1360021 | K35: ='3 Statement Model'!J74 -> 1496961.5 | L35: ='3 Statement Model'!K74 -> 1698774.7 | ... O35: ='3 Statement Model'!N74 -> 2163757.3
B36: Debt to Assets Ratio | E36: =E34/E35 -> 0.69358547 | F36: =F34/F35 -> 0.80234448 | G36: =G34/G35 -> 0.75805899 | H36: =H34/H35 -> 0.62365961 | I36: =I34/I35 -> 0.57672463 | J36: =J34/J35 -> 0.57167647 | K36: =K34/K35 -> 0.54720841 | L36: =L34/L35 -> 0.51851978 | ... O36: =O34/O35 -> 0.4934273
B38: Total Equity | E38: ='3 Statement Model'!D97 -> 1108.59 | F38: ='3 Statement Model'!E97 -> -59880.62 | G38: ='3 Statement Model'!F97 -> -62465.16 | H38: ='3 Statement Model'!G97 -> 19965 | I38: ='3 Statement Model'!H97 -> 93682 | J38: ='3 Statement Model'!I97 -> 69711 | K38: ='3 Statement Model'!J97 -> 79150.954 | L38: ='3 Statement Model'!K97 -> 113042.07 | ... O38: ='3 Statement Model'!N97 -> 224809.65
B39: Total Assets | E39: ='3 Statement Model'!D74 -> 430511.53 | F39: ='3 Statement Model'!E74 -> 459625.98 | G39: ='3 Statement Model'!F74 -> 591698.19 | H39: ='3 Statement Model'!G74 -> 822245 | I39: ='3 Statement Model'!H74 -> 1158435 | J39: ='3 Statement Model'!I74 -> 1360021 | K39: ='3 Statement Model'!J74 -> 1496961.5 | L39: ='3 Statement Model'!K74 -> 1698774.7 | ... O39: ='3 Statement Model'!N74 -> 2163757.3
B40: Equity Ratio | E40: =E38/E39 -> 0.002575053 | F40: =F38/F39 -> -0.13028119 | G40: =G38/G39 -> -0.10556929 | H40: =H38/H39 -> 0.024281084 | I40: =I38/I39 -> 0.080869449 | J40: =J38/J39 -> 0.051257297 | K40: =K38/K39 -> 0.052874408 | L40: =L38/L39 -> 0.066543296 | ... O40: =O38/O39 -> 0.10389781
B42: Profitability/Margin Ratios
B44: Gross Profit | E44: ='3 Statement Model'!D15 -> 51922.97 | F44: ='3 Statement Model'!E15 -> 64900.83 | G44: ='3 Statement Model'!F15 -> 155370.63 | H44: ='3 Statement Model'!G15 -> 283093 | I44: ='3 Statement Model'!H15 -> 326226 | J44: ='3 Statement Model'!I15 -> 285571 | K44: ='3 Statement Model'!J15 -> 345366.37 | L44: ='3 Statement Model'!K15 -> 413005.33 | ... O44: ='3 Statement Model'!N15 -> 707148.3
B45: Total Sales | E45: ='3 Statement Model'!D13 -> 146406.31 | F45: ='3 Statement Model'!E13 -> 259309.27 | G45: ='3 Statement Model'!F13 -> 544464.53 | H45: ='3 Statement Model'!G13 -> 689043 | I45: ='3 Statement Model'!H13 -> 808029 | J45: ='3 Statement Model'!I13 -> 849619 | K45: ='3 Statement Model'!J13 -> 1015783.4 | L45: ='3 Statement Model'!K13 -> 1214721.6 | ... O45: ='3 Statement Model'!N13 -> 2079847.9
B46: Gross Margin Ratios | E46: =E44/E45 -> 0.35464981 | F46: =F44/F45 -> 0.25028349 | G46: =G44/G45 -> 0.2853641 | H46: =H44/H45 -> 0.41084954 | I46: =I44/I45 -> 0.40373056 | J46: =J44/J45 -> 0.33611654 | K46: =K44/K45 -> 0.34 | L46: =L44/L45 -> 0.34 | ... O46: =O44/O45 -> 0.34
B48: EBITDA | E48: ='3 Statement Model'!D25 -> -136.05 | F48: ='3 Statement Model'!E25 -> 5473.33 | G48: ='3 Statement Model'!F25 -> 64953.5 | H48: ='3 Statement Model'!G25 -> 163175 | I48: ='3 Statement Model'!H25 -> 180583 | J48: ='3 Statement Model'!I25 -> 119834 | K48: ='3 Statement Model'!J25 -> 152367.51 | L48: ='3 Statement Model'!K25 -> 182208.23 | ... O48: ='3 Statement Model'!N25 -> 207984.79
B49: Total Sales | E49: ='3 Statement Model'!D13 -> 146406.31 | F49: ='3 Statement Model'!E13 -> 259309.27 | G49: ='3 Statement Model'!F13 -> 544464.53 | H49: ='3 Statement Model'!G13 -> 689043 | I49: ='3 Statement Model'!H13 -> 808029 | J49: ='3 Statement Model'!I13 -> 849619 | K49: ='3 Statement Model'!J13 -> 1015783.4 | L49: ='3 Statement Model'!K13 -> 1214721.6 | ... O49: ='3 Statement Model'!N13 -> 2079847.9
B50: EBITDA Margin Ratios | E50: =E48/E49 -> -0.00092926323 | F50: =F48/F49 -> 0.021107344 | G50: =G48/G49 -> 0.11929795 | H50: =H48/H49 -> 0.23681396 | I50: =I48/I49 -> 0.22348579 | J50: =J48/J49 -> 0.1410444 | K50: =K48/K49 -> 0.15 | L50: =L48/L49 -> 0.15 | ... O50: =O48/O49 -> 0.1
B52: EBIT | E52: ='3 Statement Model'!D31 -> -47130.51 | F52: ='3 Statement Model'!E31 -> -45212.67 | G52: ='3 Statement Model'!F31 -> 13923.81 | H52: ='3 Statement Model'!G31 -> 98918 | I52: ='3 Statement Model'!H31 -> 93781 | J52: ='3 Statement Model'!I31 -> 11752 | K52: ='3 Statement Model'!J31 -> 33789.378 | L52: ='3 Statement Model'!K31 -> 52452.003 | ... O52: ='3 Statement Model'!N31 -> 41077.777
B53: Total Sales | E53: ='3 Statement Model'!D13 -> 146406.31 | F53: ='3 Statement Model'!E13 -> 259309.27 | G53: ='3 Statement Model'!F13 -> 544464.53 | H53: ='3 Statement Model'!G13 -> 689043 | I53: ='3 Statement Model'!H13 -> 808029 | J53: ='3 Statement Model'!I13 -> 849619 | K53: ='3 Statement Model'!J13 -> 1015783.4 | L53: ='3 Statement Model'!K13 -> 1214721.6 | ... O53: ='3 Statement Model'!N13 -> 2079847.9
B54: EBIT Margin Ratios | E54: =E52/E53 -> -0.32191584 | F54: =F52/F53 -> -0.17435809 | G54: =G52/G53 -> 0.025573401 | H54: =H52/H53 -> 0.14355853 | I54: =I52/I53 -> 0.11606143 | J54: =J52/J53 -> 0.013832082 | K54: =K52/K53 -> 0.033264352 | L54: =L52/L53 -> 0.043180269 | ... O54: =O52/O53 -> 0.019750375
B56: Net Income | E56: ='3 Statement Model'!D42 -> -58064.27 | F56: ='3 Statement Model'!E42 -> -61618.45 | G56: ='3 Statement Model'!F42 -> -3057.89 | H56: ='3 Statement Model'!G42 -> 81725.46 | I56: ='3 Statement Model'!H42 -> 72584 | J56: ='3 Statement Model'!I42 -> -23936 | K56: ='3 Statement Model'!J42 -> 9439.9536 | L56: ='3 Statement Model'!K42 -> 33891.114 | ... O56: ='3 Statement Model'!N42 -> 46691.849
